---
title: 异常处理
date: 2021-07-27 09:59:04
categories:
- C++
---
程序运行时常会碰到一些错误，例如除数为 0、年龄为负数、数组下标越界等，这些错误如果不能发现并加以处理，很可能会导致程序崩溃。

**举例**：

```c++
#include <iostream>
#include <string>
using namespace std;
int main(){
    string str = "http://c.biancheng.net";
    char ch1 = str[100];  //下标越界，ch1为垃圾值
    cout<<ch1<<endl;
    char ch2 = str.at(100);  //下标越界，抛出异常
    cout<<ch2<<endl;
    return 0;
}
```

输出为：

![image-20210725082318460](./imags/image-20210725082318460.png)

at() 是 string 类的一个成员函数，它会根据下标来返回字符串的一个字符。与`[ ]`不同，at() 会检查下标是否越界，如果越界就抛出一个异常；而`[ ]`不做检查，不管下标是多少都会照常访问。

上面的代码中，下标 100 显然超出了字符串 str 的长度。由于第 6 行代码不会检查下标越界，虽然有逻辑错误，但是程序能够正常运行。而第 8 行代码则不同，at() 函数检测到下标越界会抛出一个异常，这个异常可以由程序员处理，但是我们在代码中并没有处理，所以系统只能执行默认的操作，也即终止程序执行。

## 捕获异常

try

catch

```C++
try{
    // 可能抛出异常的语句
}catch(exceptionType variable){
    // 处理异常的语句
}
```

修改例子中的代码

```c++
#include <iostream>
#include <string>
#include <exception>
using namespace std;
int main(){
    string str = "http://c.biancheng.net";
  
    try{
        char ch1 = str[100];
        cout<<ch1<<endl;
    }catch(exception e){
        cout<<"[1]out of bound!"<<endl;
    } //这里由于不检查下界，无法捕获异常
    try{
        char ch2 = str.at(100);
        cout<<ch2<<endl;
    }catch(exception &e){  //exception类位于<exception>头文件中
        cout<<"[2]out of bound!"<<endl;
    }
    return 0;
}
```

![image-20210725082739208](../imags/image-20210725082739208.png)



说得直接一点，检测到异常后程序的执行流会发生跳转，从异常点跳转到 catch 所在的位置，位于异常点之后的、**并且在当前 try 块内的语句就都不会再执行了**；即使 catch 语句成功地处理了错误，程序的执行流也不会再回退到异常点，所以这些语句永远都没有执行的机会了

执行完 catch 块所包含的代码后，程序会继续执行 catch 块后面的代码，就恢复了正常的执行流。

#### 发生异常的位置

异常可以发生在当前的 try 块中，也可以发生在 try 块所调用的某个函数中，或者是所调用的函数又调用了另外的一个函数，这个另外的函数中发生了异常。这些异常，都可以被 try 检测到。

发生异常后，程序的执行流会沿着函数的调用链往前回退，直到遇见 try 才停止。在这个回退过程中，调用链中剩下的代码（所有函数中未被执行的代码）都会被跳过，没有执行的机会了

#### 多级catch

对于 catch，异常是在运行阶段产生的，它可以是任何类型，没法提前预测，所以不能在编译阶段判断类型是否正确，只能等到程序运行后，真的抛出异常了，再将异常类型和 catch 能处理的类型进行匹配，匹配成功的话就“调用”当前的 catch，否则就忽略当前的 catch。

```c++
#include <iostream>
#include <string>
using namespace std;
class Base{ };
class Derived: public Base{ };
int main(){
    try{
        throw Derived();  //抛出自己的异常类型，实际上是创建一个Derived类型的匿名对象
        cout<<"This statement will not be executed."<<endl;
    }catch(int){
        cout<<"Exception type: int"<<endl;
    }catch(char *){
        cout<<"Exception type: cahr *"<<endl;
    }catch(Base){  //匹配成功（向上转型）
        cout<<"Exception type: Base"<<endl;
    }catch(Derived){
        cout<<"Exception type: Derived"<<endl;
    }
    return 0;
}
```



## 抛出异常

异常处理流程为：抛出（Throw）--> 检测（Try） --> 捕获（Catch）

在 C++ 中，我们使用 throw 关键字来显式地抛出异常，它的用法为：

`throw exceptionData;`

exceptionData 是“异常数据”的意思，它可以包含任意的信息，完全有程序员决定。exceptionData 可以是 int、float、bool 等基本类型，也可以是[指针](http://c.biancheng.net/c/80/)、数组、字符串、结构体、类等聚合类型，请看下面的例子：

```c++
char str[] = "http://c.biancheng.net";
char *pstr = str;
class Base{};
Base obj;

throw 100;  //int 类型
throw str;  //数组类型
throw pstr;  //指针类型
throw obj;  //对象类型
```

```c++
#include <iostream>
#include <cstdlib>
using namespace std;
//自定义的异常类型
class OutOfRange{
public:
    OutOfRange(): m_flag(1){ };
    OutOfRange(int len, int index): m_len(len), m_index(index), m_flag(2){ }
public:
    void what() const;  //获取具体的错误信息
private:
    int m_flag;  //不同的flag表示不同的错误
    int m_len;  //当前数组的长度
    int m_index;  //当前使用的数组下标
};
void OutOfRange::what() const {
    if(m_flag == 1){
        cout<<"Error: empty array, no elements to pop."<<endl;
    }else if(m_flag == 2){
        cout<<"Error: out of range( array length "<<m_len<<", access index "<<m_index<<" )"<<endl;
    }else{
        cout<<"Unknown exception."<<endl;
    }
}
//实现动态数组
class Array{
public:
    Array();
    ~Array(){ free(m_p); };
public:
    int operator[](int i) const;  //获取数组元素
    int push(int ele);  //在末尾插入数组元素
    int pop();  //在末尾删除数组元素
    int length() const{ return m_len; };  //获取数组长度
private:
    int m_len;  //数组长度
    int m_capacity;  //当前的内存能容纳多少个元素
    int *m_p;  //内存指针
private:
    static const int m_stepSize = 50;  //每次扩容的步长
};
Array::Array(){
    m_p = (int*)malloc( sizeof(int) * m_stepSize );
    m_capacity = m_stepSize;
    m_len = 0;
}
int Array::operator[](int index) const {
    if( index<0 || index>=m_len ){  //判断是否越界
        throw OutOfRange(m_len, index);  //抛出异常（创建一个匿名对象）
    }
    return *(m_p + index);
}
int Array::push(int ele){
    if(m_len >= m_capacity){  //如果容量不足就扩容
        m_capacity += m_stepSize;
        m_p = (int*)realloc( m_p, sizeof(int) * m_capacity );  //扩容
    }
    *(m_p + m_len) = ele;
    m_len++;
    return m_len-1;
}
int Array::pop(){
    if(m_len == 0){
         throw OutOfRange();  //抛出异常（创建一个匿名对象）
    }
    m_len--;
    return *(m_p + m_len);
}
//打印数组元素
void printArray(Array &arr){
    int len = arr.length();
    //判断数组是否为空
    if(len == 0){
        cout<<"Empty array! No elements to print."<<endl;
        return;
    }
    for(int i=0; i<len; i++){
        if(i == len-1){
            cout<<arr[i]<<endl;
        }else{
            cout<<arr[i]<<", ";
        }
    }
}
int main(){
    Array nums;
    //向数组中添加十个元素
    for(int i=0; i<10; i++){
        nums.push(i);
    }
    printArray(nums);
    //尝试访问第20个元素
    try{
        cout<<nums[20]<<endl;
    }catch(OutOfRange &e){
        e.what();
    }
    //尝试弹出20个元素
    try{
        for(int i=0; i<20; i++){
            nums.pop();
        }
    }catch(OutOfRange &e){
        e.what();
    }
    printArray(nums);
    return 0;
}
```



参考：http://c.biancheng.net/cplus/exception/