---
title: 异常——抛出异常
date: 2021-07-27 10:04:43
categories:
- Python
---
## 1. 异常

| 异常类型          | 含义                                                         | 实例                                                         |
| ----------------- | ------------------------------------------------------------ | ------------------------------------------------------------ |
| AssertionError    | 当 assert 关键字后的条件为假时，程序运行会停止并抛出 AssertionError 异常 | >>> demo_list = ['C语言中文网'] >>> assert len(demo_list) > 0 >>> demo_list.pop() 'C语言中文网' >>> assert len(demo_list) > 0 Traceback (most recent call last):  File "<pyshell#6>", line 1, in <module>   assert len(demo_list) > 0 AssertionError |
| AttributeError    | 当试图访问的对象属性不存在时抛出的异常                       | >>> demo_list = ['C语言中文网'] >>> demo_list.len Traceback (most recent call last):  File "<pyshell#10>", line 1, in <module>   demo_list.len AttributeError: 'list' object has no attribute 'len' |
| IndexError        | 索引超出序列范围会引发此异常                                 | >>> demo_list = ['C语言中文网'] >>> demo_list[3] Traceback (most recent call last):  File "<pyshell#8>", line 1, in <module>   demo_list[3] IndexError: list index out of range |
| KeyError          | 字典中查找一个不存在的关键字时引发此异常                     | >>> demo_dict={'C语言中文网':"c.biancheng.net"} >>> demo_dict["C语言"] Traceback (most recent call last):  File "<pyshell#12>", line 1, in <module>   demo_dict["C语言"] KeyError: 'C语言' |
| NameError         | 尝试访问一个未声明的变量时，引发此异常                       | >>> C语言中文网 Traceback (most recent call last):  File "<pyshell#15>", line 1, in <module>   C语言中文网 NameError: name 'C语言中文网' is not defined |
| TypeError         | 不同类型数据之间的无效操作                                   | >>> 1+'C语言中文网' Traceback (most recent call last):  File "<pyshell#17>", line 1, in <module>   1+'C语言中文网' TypeError: unsupported operand type(s) for +: 'int' and 'str' |
| ZeroDivisionError | 除法运算中除数为 0 引发此异常                                | >>> a = 1/0 Traceback (most recent call last):  File "<pyshell#2>", line 1, in <module>   a = 1/0 ZeroDivisionError: division by zero |

## 2. 异常捕获

`try--except`

try： 捕获异常

except： 处理异常，处理完继续运行

```python
try:
  可能产生异常的代码块
except [ (Error1, Error2, ... ) [as e] ]:
  处理异常的代码块1
except [ (Error3, Error4, ... ) [as e] ]:
  处理异常的代码块2
except [Exception]:
  处理其它异常
```

```python
try:
    a = int(input("输入被除数："))
    b = int(input("输入除数："))
    c = a / b
    print("您输入的两个数相除的结果是：", c )
except (ValueError, ArithmeticError):
    print("程序发生了数字格式异常、算术异常之一")
except :
    print("未知异常")
print("程序继续运行")
```

上面程序中，第 6 行代码使用了（ValueError, ArithmeticError）来指定所捕获的异常类型，这就表明该 except 块可以同时捕获这 2 种类型的异常；第 8 行代码只有 except 关键字，并未指定具体要捕获的异常类型，这种省略异常类的 except 语句也是合法的，它表示可捕获所有类型的异常，一般会作为异常捕获的最后一个 except 块。

#### 作用

事实上，不管程序代码块是否处于 try 块中，甚至包括 except 块中的代码，只要执行该代码块时出现了异常，系统都会自动生成对应类型的异常。但是，如果此段程序没有用 try 包裹，又或者没有为该异常配置处理它的 except 块，则 Python 解释器将无法处理，程序就会停止运行；反之，如果程序发生的异常经 try 捕获并由 except 处理完成，则**程序可以继续执行**。

## 3. 手动抛出异常

`raise`

raise 语句的基本语法格式为：

raise [exceptionName [(reason)]]



### 4. assert断言

直接让条件不满足时程序崩溃

https://blog.csdn.net/qq_38906523/article/details/81099030

参考：https://www.liaoxuefeng.com/wiki/1016959663602400/1017598873256736

